Workbook

Sheet Resumen
A1: Planificación Scrum — Argüello Infancias — Sistema de gestión de residencia NNyA (web + mobile)
A2: Estimación realista para un equipo de 4 estudiantes de 3er año de Analista de Sistemas
A4: Supuestos
A5: Fecha de inicio | B5: 46093 | C5: Inicio del proyecto (dato del equipo)
A6: Fecha de corte del estado | B6: 46324 | C6: Los sprints que terminan antes de esta fecha figuran como Completados
A7: Duración de sprint (días) | B7: 14 | C7: Scrum, sprints de 2 semanas
A8: Horas por semana por integrante | B8: 12 | C8: Dedicación declarada por el equipo (cursan otras materias en paralelo)
A9: Ceremonias por sprint (h/persona) | B9: 4 | C9: Planning 2 h + dailies asincrónicas ~1 h + review/retro 1 h
A10: Capacidad normal (h tareas/persona/sprint) | B10: =B8*2-B9 -> 20 | C10: Horas semanales × 2 − ceremonias
A11: Capacidad reducida (h tareas/persona/sprint) | B11: 14 | C11: Sprints con parciales o finales: 18 h − ceremonias
A13: Equipo y carga total
A14: Integrante | B14: Horas tareas | C14: Rol | D14: Ceremonias (h) | E14: Horas totales | F14: % del total
A15: Jordy | B15: =SUMIFS(Backlog!$I:$I,Backlog!$F:$F,A15) -> 344 | C15: Líder de proyecto / Scrum Master · Backend y base de datos (Supabase, RLS) | D15: =$B$9*19 -> 76 | E15: =B15+D15 -> 420 | F15: =E15/$E$19 -> 0.25
A16: Meli | B16: =SUMIFS(Backlog!$I:$I,Backlog!$F:$F,A16) -> 344 | C16: QA y testing · Integraciones (Didit) | D16: =$B$9*19 -> 76 | E16: =B16+D16 -> 420 | F16: =E16/$E$19 -> 0.25
A17: Cami | B17: =SUMIFS(Backlog!$I:$I,Backlog!$F:$F,A17) -> 344 | C17: Frontend y UX · Innovaciones de interfaz | D17: =$B$9*19 -> 76 | E17: =B17+D17 -> 420 | F17: =E17/$E$19 -> 0.25
A18: Sofi | B18: =SUMIFS(Backlog!$I:$I,Backlog!$F:$F,A18) -> 344 | C18: Análisis funcional, specs y documentación · Desarrollo mobile | D18: =$B$9*19 -> 76 | E18: =B18+D18 -> 420 | F18: =E18/$E$19 -> 0.25
A19: Total equipo | B19: =SUM(B15:B18) -> 1376 | D19: =SUM(D15:D18) -> 304 | E19: =SUM(E15:E18) -> 1680 | F19: =SUM(F15:F18) -> 1
A21: Indicadores
A22: Sprints | B22: =COUNTA(Sprints!A5:A23) -> 19
A23: Fecha de fin estimada | B23: =MAX(Sprints!D5:D23) -> 46372
A24: Semanas calendario | B24: =ROUND((B23-B5+1)/7,0) -> 40
A25: Sprints completados | B25: =COUNTIF(Sprints!J5:J23,"Completado") -> 15
A26: Avance por horas (%) | B26: =SUMIFS(Backlog!$I:$I,Backlog!$J:$J,"Completado")/B19 -> 0.80232558
A28: Hitos
A29: Fin del análisis: specs 01–12 aprobadas | B29: 46148
A30: Primer despliegue en Vercel | B30: 46162
A31: MVP web: ABM maestras + legajo | B31: 46204
A32: Entrega Unidad I — app mobile | B32: 46270
A33: Innovación 1 (Didit) integrada | B33: 46316
A34: Release 1.0 web + mobile | B34: 46358
A35: Entrega final y defensa | B35: 46372
A37: Convención: azul = dato editable · negro = fórmula · verde = referencia a otra hoja

Sheet Sprints
A1: Sprints
A2: Capacidad del equipo vs. horas planificadas por sprint
A4: Sprint | B4: Fase | C4: Inicio | D4: Fin | E4: Objetivo | F4: Capacidad | G4: Nota | H4: Cap. equipo (h) | I4: Planificado (h) | J4: Estado | K4: % uso
A5: 0 | B5: Fase 1 — Inicio y análisis | C5: 46093 | D5: 46106 | E5: Inicio del proyecto y relevamiento inicial | F5: normal | H5: =IF(F5="normal",Resumen!$B$10,Resumen!$B$11)*4 -> 80 | I5: =SUMIFS(Backlog!$I:$I,Backlog!$B:$B,A5) -> 80 | J5: =IF(D5<Resumen!$B$6,"Completado",IF(C5<=Resumen!$B$6,"En curso","Planificado")) -> Completado | K5: =IF(H5=0,0,I5/H5) -> 1
A6: 1 | B6: Fase 1 — Inicio y análisis | C6: 46107 | D6: 46120 | E6: Procesos del negocio | F6: normal | H6: =IF(F6="normal",Resumen!$B$10,Resumen!$B$11)*4 -> 80 | I6: =SUMIFS(Backlog!$I:$I,Backlog!$B:$B,A6) -> 80 | J6: =IF(D6<Resumen!$B$6,"Completado",IF(C6<=Resumen!$B$6,"En curso","Planificado")) -> Completado | K6: =IF(H6=0,0,I6/H6) -> 1
A7: 2 | B7: Fase 1 — Inicio y análisis | C7: 46121 | D7: 46134 | E7: Requerimientos y modelo de datos | F7: normal | H7: =IF(F7="normal",Resumen!$B$10,Resumen!$B$11)*4 -> 80 | I7: =SUMIFS(Backlog!$I:$I,Backlog!$B:$B,A7) -> 80 | J7: =IF(D7<Resumen!$B$6,"Completado",IF(C7<=Resumen!$B$6,"En curso","Planificado")) -> Completado | K7: =IF(H7=0,0,I7/H7) -> 1
A8: 3 | B8: Fase 1 — Inicio y análisis | C8: 46135 | D8: 46148 | E8: Arquitectura y especificación funcional | F8: reducida | G8: Parciales 1er cuatrimestre | H8: =IF(F8="normal",Resumen!$B$10,Resumen!$B$11)*4 -> 56 | I8: =SUMIFS(Backlog!$I:$I,Backlog!$B:$B,A8) -> 56 | J8: =IF(D8<Resumen!$B$6,"Completado",IF(C8<=Resumen!$B$6,"En curso","Planificado")) -> Completado | K8: =IF(H8=0,0,I8/H8) -> 1
A9: 4 | B9: Fase 2 — Construcción web | C9: 46149 | D9: 46162 | E9: Setup técnico y sistema de diseño | F9: normal | H9: =IF(F9="normal",Resumen!$B$10,Resumen!$B$11)*4 -> 80 | I9: =SUMIFS(Backlog!$I:$I,Backlog!$B:$B,A9) -> 80 | J9: =IF(D9<Resumen!$B$6,"Completado",IF(C9<=Resumen!$B$6,"En curso","Planificado")) -> Completado | K9: =IF(H9=0,0,I9/H9) -> 1
A10: 5 | B10: Fase 2 — Construcción web | C10: 46163 | D10: 46176 | E10: Autenticación y ABM maestras | F10: normal | H10: =IF(F10="normal",Resumen!$B$10,Resumen!$B$11)*4 -> 80 | I10: =SUMIFS(Backlog!$I:$I,Backlog!$B:$B,A10) -> 80 | J10: =IF(D10<Resumen!$B$6,"Completado",IF(C10<=Resumen!$B$6,"En curso","Planificado")) -> Completado | K10: =IF(H10=0,0,I10/H10) -> 1
A11: 6 | B11: Fase 2 — Construcción web | C11: 46177 | D11: 46190 | E11: Legajo del NNyA | F11: reducida | G11: Parciales | H11: =IF(F11="normal",Resumen!$B$10,Resumen!$B$11)*4 -> 56 | I11: =SUMIFS(Backlog!$I:$I,Backlog!$B:$B,A11) -> 56 | J11: =IF(D11<Resumen!$B$6,"Completado",IF(C11<=Resumen!$B$6,"En curso","Planificado")) -> Completado | K11: =IF(H11=0,0,I11/H11) -> 1
A12: 7 | B12: Fase 2 — Construcción web | C12: 46191 | D12: 46204 | E12: Informes e intervenciones | F12: reducida | G12: Finales 1er cuatrimestre | H12: =IF(F12="normal",Resumen!$B$10,Resumen!$B$11)*4 -> 56 | I12: =SUMIFS(Backlog!$I:$I,Backlog!$B:$B,A12) -> 56 | J12: =IF(D12<Resumen!$B$6,"Completado",IF(C12<=Resumen!$B$6,"En curso","Planificado")) -> Completado | K12: =IF(H12=0,0,I12/H12) -> 1
A13: 8 | B13: Fase 2 — Construcción web | C13: 46219 | D13: 46232 | E13: Acompañamiento diario y salud | F13: normal | H13: =IF(F13="normal",Resumen!$B$10,Resumen!$B$11)*4 -> 80 | I13: =SUMIFS(Backlog!$I:$I,Backlog!$B:$B,A13) -> 80 | J13: =IF(D13<Resumen!$B$6,"Completado",IF(C13<=Resumen!$B$6,"En curso","Planificado")) -> Completado | K13: =IF(H13=0,0,I13/H13) -> 1
A14: 9 | B14: Fase 2 — Construcción web | C14: 46233 | D14: 46246 | E14: Incidentes, alertas y turnos | F14: normal | H14: =IF(F14="normal",Resumen!$B$10,Resumen!$B$11)*4 -> 80 | I14: =SUMIFS(Backlog!$I:$I,Backlog!$B:$B,A14) -> 80 | J14: =IF(D14<Resumen!$B$6,"Completado",IF(C14<=Resumen!$B$6,"En curso","Planificado")) -> Completado | K14: =IF(H14=0,0,I14/H14) -> 1
A15: 10 | B15: Fase 2 — Construcción web | C15: 46247 | D15: 46260 | E15: Egreso, tutela y seguimiento | F15: normal | H15: =IF(F15="normal",Resumen!$B$10,Resumen!$B$11)*4 -> 80 | I15: =SUMIFS(Backlog!$I:$I,Backlog!$B:$B,A15) -> 80 | J15: =IF(D15<Resumen!$B$6,"Completado",IF(C15<=Resumen!$B$6,"En curso","Planificado")) -> Completado | K15: =IF(H15=0,0,I15/H15) -> 1
A16: 11 | B16: Fase 3 — Mobile e innovación | C16: 46261 | D16: 46274 | E16: Inicio mobile + reportes SENAF | F16: normal | H16: =IF(F16="normal",Resumen!$B$10,Resumen!$B$11)*4 -> 80 | I16: =SUMIFS(Backlog!$I:$I,Backlog!$B:$B,A16) -> 80 | J16: =IF(D16<Resumen!$B$6,"Completado",IF(C16<=Resumen!$B$6,"En curso","Planificado")) -> Completado | K16: =IF(H16=0,0,I16/H16) -> 1
A17: 12 | B17: Fase 3 — Mobile e innovación | C17: 46275 | D17: 46288 | E17: Mobile F1 + dashboard | F17: normal | H17: =IF(F17="normal",Resumen!$B$10,Resumen!$B$11)*4 -> 80 | I17: =SUMIFS(Backlog!$I:$I,Backlog!$B:$B,A17) -> 80 | J17: =IF(D17<Resumen!$B$6,"Completado",IF(C17<=Resumen!$B$6,"En curso","Planificado")) -> Completado | K17: =IF(H17=0,0,I17/H17) -> 1
A18: 13 | B18: Fase 3 — Mobile e innovación | C18: 46289 | D18: 46302 | E18: Mobile F2/F3 + análisis Didit | F18: reducida | G18: Parciales 2do cuatrimestre | H18: =IF(F18="normal",Resumen!$B$10,Resumen!$B$11)*4 -> 56 | I18: =SUMIFS(Backlog!$I:$I,Backlog!$B:$B,A18) -> 56 | J18: =IF(D18<Resumen!$B$6,"Completado",IF(C18<=Resumen!$B$6,"En curso","Planificado")) -> Completado | K18: =IF(H18=0,0,I18/H18) -> 1
A19: 14 | B19: Fase 3 — Mobile e innovación | C19: 46303 | D19: 46316 | E19: Mobile F4/F5 + Innovación 1 (Didit) | F19: normal | H19: =IF(F19="normal",Resumen!$B$10,Resumen!$B$11)*4 -> 80 | I19: =SUMIFS(Backlog!$I:$I,Backlog!$B:$B,A19) -> 80 | J19: =IF(D19<Resumen!$B$6,"Completado",IF(C19<=Resumen!$B$6,"En curso","Planificado")) -> Completado | K19: =IF(H19=0,0,I19/H19) -> 1
A20: 15 | B20: Fase 3 — Mobile e innovación | C20: 46317 | D20: 46330 | E20: Mobile F6 + cierre Innovación 1 | F20: normal | H20: =IF(F20="normal",Resumen!$B$10,Resumen!$B$11)*4 -> 80 | I20: =SUMIFS(Backlog!$I:$I,Backlog!$B:$B,A20) -> 80 | J20: =IF(D20<Resumen!$B$6,"Completado",IF(C20<=Resumen!$B$6,"En curso","Planificado")) -> En curso | K20: =IF(H20=0,0,I20/H20) -> 1
A21: 16 | B21: Fase 4 — Pruebas, despliegue y cierre | C21: 46331 | D21: 46344 | E21: Testing integral y seguridad | F21: reducida | G21: Parciales 2do cuatrimestre | H21: =IF(F21="normal",Resumen!$B$10,Resumen!$B$11)*4 -> 56 | I21: =SUMIFS(Backlog!$I:$I,Backlog!$B:$B,A21) -> 56 | J21: =IF(D21<Resumen!$B$6,"Completado",IF(C21<=Resumen!$B$6,"En curso","Planificado")) -> Planificado | K21: =IF(H21=0,0,I21/H21) -> 1
A22: 17 | B22: Fase 4 — Pruebas, despliegue y cierre | C22: 46345 | D22: 46358 | E22: Documentación y despliegue | F22: normal | H22: =IF(F22="normal",Resumen!$B$10,Resumen!$B$11)*4 -> 80 | I22: =SUMIFS(Backlog!$I:$I,Backlog!$B:$B,A22) -> 80 | J22: =IF(D22<Resumen!$B$6,"Completado",IF(C22<=Resumen!$B$6,"En curso","Planificado")) -> Planificado | K22: =IF(H22=0,0,I22/H22) -> 1
A23: 18 | B23: Fase 4 — Pruebas, despliegue y cierre | C23: 46359 | D23: 46372 | E23: Cierre y defensa | F23: reducida | G23: Mesas de examen | H23: =IF(F23="normal",Resumen!$B$10,Resumen!$B$11)*4 -> 56 | I23: =SUMIFS(Backlog!$I:$I,Backlog!$B:$B,A23) -> 56 | J23: =IF(D23<Resumen!$B$6,"Completado",IF(C23<=Resumen!$B$6,"En curso","Planificado")) -> Planificado | K23: =IF(H23=0,0,I23/H23) -> 1
G24: Total | H24: =SUM(H5:H23) -> 1376 | I24: =SUM(I5:I23) -> 1376
A26: Receso invernal (sin sprint): 02/07/2026 – 15/07/2026

Sheet Backlog
A1: Backlog del proyecto
A2: Una fila por tarea. Editá Sprint, Responsable u Horas (azul) y se recalculan Sprints, Carga y Gantt
A4: ID | B4: Sprint | C4: Fase | D4: Área | E4: Tarea | F4: Responsable | G4: Inicio | H4: Fin | I4: Horas | J4: Estado
A5: T-001 | B5: 0 | C5: =INDEX(Sprints!$B$5:$B$23,MATCH(B5,Sprints!$A$5:$A$23,0)) -> Fase 1 — Inicio y análisis | D5: Gestión | E5: Kickoff, conformación del equipo y tablero Scrum en GitHub Projects | F5: Jordy | G5: =INDEX(Sprints!$C$5:$C$23,MATCH(B5,Sprints!$A$5:$A$23,0)) -> 46093 | H5: =INDEX(Sprints!$D$5:$D$23,MATCH(B5,Sprints!$A$5:$A$23,0)) -> 46106 | I5: 8 | J5: =INDEX(Sprints!$J$5:$J$23,MATCH(B5,Sprints!$A$5:$A$23,0)) -> Completado
A6: T-002 | B6: 0 | C6: =INDEX(Sprints!$B$5:$B$23,MATCH(B6,Sprints!$A$5:$A$23,0)) -> Fase 1 — Inicio y análisis | D6: Análisis | E6: Entrevista inicial con la institución y presentación del proyecto | F6: Jordy | G6: =INDEX(Sprints!$C$5:$C$23,MATCH(B6,Sprints!$A$5:$A$23,0)) -> 46093 | H6: =INDEX(Sprints!$D$5:$D$23,MATCH(B6,Sprints!$A$5:$A$23,0)) -> 46106 | I6: 12 | J6: =INDEX(Sprints!$J$5:$J$23,MATCH(B6,Sprints!$A$5:$A$23,0)) -> Completado
A7: T-003 | B7: 0 | C7: =INDEX(Sprints!$B$5:$B$23,MATCH(B7,Sprints!$A$5:$A$23,0)) -> Fase 1 — Inicio y análisis | D7: Análisis | E7: Relevamiento de documentación existente (planillas, legajos en papel) | F7: Meli | G7: =INDEX(Sprints!$C$5:$C$23,MATCH(B7,Sprints!$A$5:$A$23,0)) -> 46093 | H7: =INDEX(Sprints!$D$5:$D$23,MATCH(B7,Sprints!$A$5:$A$23,0)) -> 46106 | I7: 10 | J7: =INDEX(Sprints!$J$5:$J$23,MATCH(B7,Sprints!$A$5:$A$23,0)) -> Completado
A8: T-004 | B8: 0 | C8: =INDEX(Sprints!$B$5:$B$23,MATCH(B8,Sprints!$A$5:$A$23,0)) -> Fase 1 — Inicio y análisis | D8: Gestión | E8: Acta de constitución y alcance preliminar | F8: Meli | G8: =INDEX(Sprints!$C$5:$C$23,MATCH(B8,Sprints!$A$5:$A$23,0)) -> 46093 | H8: =INDEX(Sprints!$D$5:$D$23,MATCH(B8,Sprints!$A$5:$A$23,0)) -> 46106 | I8: 10 | J8: =INDEX(Sprints!$J$5:$J$23,MATCH(B8,Sprints!$A$5:$A$23,0)) -> Completado
A9: T-005 | B9: 0 | C9: =INDEX(Sprints!$B$5:$B$23,MATCH(B9,Sprints!$A$5:$A$23,0)) -> Fase 1 — Inicio y análisis | D9: Análisis | E9: Relevamiento de actores, roles y usuarios del sistema | F9: Sofi | G9: =INDEX(Sprints!$C$5:$C$23,MATCH(B9,Sprints!$A$5:$A$23,0)) -> 46093 | H9: =INDEX(Sprints!$D$5:$D$23,MATCH(B9,Sprints!$A$5:$A$23,0)) -> 46106 | I9: 20 | J9: =INDEX(Sprints!$J$5:$J$23,MATCH(B9,Sprints!$A$5:$A$23,0)) -> Completado
A10: T-006 | B10: 0 | C10: =INDEX(Sprints!$B$5:$B$23,MATCH(B10,Sprints!$A$5:$A$23,0)) -> Fase 1 — Inicio y análisis | D10: Análisis | E10: Relevamiento de herramientas actuales y problemáticas | F10: Cami | G10: =INDEX(Sprints!$C$5:$C$23,MATCH(B10,Sprints!$A$5:$A$23,0)) -> 46093 | H10: =INDEX(Sprints!$D$5:$D$23,MATCH(B10,Sprints!$A$5:$A$23,0)) -> 46106 | I10: 12 | J10: =INDEX(Sprints!$J$5:$J$23,MATCH(B10,Sprints!$A$5:$A$23,0)) -> Completado
A11: T-007 | B11: 0 | C11: =INDEX(Sprints!$B$5:$B$23,MATCH(B11,Sprints!$A$5:$A$23,0)) -> Fase 1 — Inicio y análisis | D11: Documentación | E11: Presentación del proyecto (Encuentro 1) | F11: Cami | G11: =INDEX(Sprints!$C$5:$C$23,MATCH(B11,Sprints!$A$5:$A$23,0)) -> 46093 | H11: =INDEX(Sprints!$D$5:$D$23,MATCH(B11,Sprints!$A$5:$A$23,0)) -> 46106 | I11: 8 | J11: =INDEX(Sprints!$J$5:$J$23,MATCH(B11,Sprints!$A$5:$A$23,0)) -> Completado
A12: T-008 | B12: 1 | C12: =INDEX(Sprints!$B$5:$B$23,MATCH(B12,Sprints!$A$5:$A$23,0)) -> Fase 1 — Inicio y análisis | D12: Análisis | E12: Proceso de ingreso y admisión (Ley 9944 / Ley 26.061) | F12: Jordy | G12: =INDEX(Sprints!$C$5:$C$23,MATCH(B12,Sprints!$A$5:$A$23,0)) -> 46107 | H12: =INDEX(Sprints!$D$5:$D$23,MATCH(B12,Sprints!$A$5:$A$23,0)) -> 46120 | I12: 20 | J12: =INDEX(Sprints!$J$5:$J$23,MATCH(B12,Sprints!$A$5:$A$23,0)) -> Completado
A13: T-009 | B13: 1 | C13: =INDEX(Sprints!$B$5:$B$23,MATCH(B13,Sprints!$A$5:$A$23,0)) -> Fase 1 — Inicio y análisis | D13: Análisis | E13: Procesos de legajo, documentos e informes | F13: Meli | G13: =INDEX(Sprints!$C$5:$C$23,MATCH(B13,Sprints!$A$5:$A$23,0)) -> 46107 | H13: =INDEX(Sprints!$D$5:$D$23,MATCH(B13,Sprints!$A$5:$A$23,0)) -> 46120 | I13: 20 | J13: =INDEX(Sprints!$J$5:$J$23,MATCH(B13,Sprints!$A$5:$A$23,0)) -> Completado
A14: T-010 | B14: 1 | C14: =INDEX(Sprints!$B$5:$B$23,MATCH(B14,Sprints!$A$5:$A$23,0)) -> Fase 1 — Inicio y análisis | D14: Análisis | E14: Procesos de acompañamiento diario, salud e incidentes | F14: Sofi | G14: =INDEX(Sprints!$C$5:$C$23,MATCH(B14,Sprints!$A$5:$A$23,0)) -> 46107 | H14: =INDEX(Sprints!$D$5:$D$23,MATCH(B14,Sprints!$A$5:$A$23,0)) -> 46120 | I14: 20 | J14: =INDEX(Sprints!$J$5:$J$23,MATCH(B14,Sprints!$A$5:$A$23,0)) -> Completado
A15: T-011 | B15: 1 | C15: =INDEX(Sprints!$B$5:$B$23,MATCH(B15,Sprints!$A$5:$A$23,0)) -> Fase 1 — Inicio y análisis | D15: Análisis | E15: Procesos de egreso, tutela y coordinación judicial / SENAF | F15: Cami | G15: =INDEX(Sprints!$C$5:$C$23,MATCH(B15,Sprints!$A$5:$A$23,0)) -> 46107 | H15: =INDEX(Sprints!$D$5:$D$23,MATCH(B15,Sprints!$A$5:$A$23,0)) -> 46120 | I15: 20 | J15: =INDEX(Sprints!$J$5:$J$23,MATCH(B15,Sprints!$A$5:$A$23,0)) -> Completado
A16: T-012 | B16: 2 | C16: =INDEX(Sprints!$B$5:$B$23,MATCH(B16,Sprints!$A$5:$A$23,0)) -> Fase 1 — Inicio y análisis | D16: Análisis | E16: Modelo de datos (DER) y diccionario de datos | F16: Jordy | G16: =INDEX(Sprints!$C$5:$C$23,MATCH(B16,Sprints!$A$5:$A$23,0)) -> 46121 | H16: =INDEX(Sprints!$D$5:$D$23,MATCH(B16,Sprints!$A$5:$A$23,0)) -> 46134 | I16: 20 | J16: =INDEX(Sprints!$J$5:$J$23,MATCH(B16,Sprints!$A$5:$A$23,0)) -> Completado
... A85: T-081 | B85: 18 | C85: =INDEX(Sprints!$B$5:$B$23,MATCH(B85,Sprints!$A$5:$A$23,0)) -> Fase 4 — Pruebas, despliegue y cierre | D85: QA | E85: Ensayo de la demo y correcciones finales | F85: Meli | G85: =INDEX(Sprints!$C$5:$C$23,MATCH(B85,Sprints!$A$5:$A$23,0)) -> 46359 | H85: =INDEX(Sprints!$D$5:$D$23,MATCH(B85,Sprints!$A$5:$A$23,0)) -> 46372 | I85: 14 | J85: =INDEX(Sprints!$J$5:$J$23,MATCH(B85,Sprints!$A$5:$A$23,0)) -> Planificado
H86: Total | I86: =SUM(I5:I85) -> 1376

Sheet Carga por integrante
A1: Carga por integrante y sprint (h de tareas)
A2: Rojo = supera la capacidad del sprint
A4: Sprint | B4: Capacidad/persona | C4: Jordy | D4: Meli | E4: Cami | F4: Sofi | G4: Total
A5: 0 | B5: =IF(Sprints!F5="normal",Resumen!$B$10,Resumen!$B$11) -> 20 | C5: =SUMIFS(Backlog!$I:$I,Backlog!$B:$B,$A5,Backlog!$F:$F,"Jordy") -> 20 | D5: =SUMIFS(Backlog!$I:$I,Backlog!$B:$B,$A5,Backlog!$F:$F,"Meli") -> 20 | E5: =SUMIFS(Backlog!$I:$I,Backlog!$B:$B,$A5,Backlog!$F:$F,"Cami") -> 20 | F5: =SUMIFS(Backlog!$I:$I,Backlog!$B:$B,$A5,Backlog!$F:$F,"Sofi") -> 20 | G5: =SUM(C5:F5) -> 80
A6: 1 | B6: =IF(Sprints!F6="normal",Resumen!$B$10,Resumen!$B$11) -> 20 | C6: =SUMIFS(Backlog!$I:$I,Backlog!$B:$B,$A6,Backlog!$F:$F,"Jordy") -> 20 | D6: =SUMIFS(Backlog!$I:$I,Backlog!$B:$B,$A6,Backlog!$F:$F,"Meli") -> 20 | E6: =SUMIFS(Backlog!$I:$I,Backlog!$B:$B,$A6,Backlog!$F:$F,"Cami") -> 20 | F6: =SUMIFS(Backlog!$I:$I,Backlog!$B:$B,$A6,Backlog!$F:$F,"Sofi") -> 20 | G6: =SUM(C6:F6) -> 80
A7: 2 | B7: =IF(Sprints!F7="normal",Resumen!$B$10,Resumen!$B$11) -> 20 | C7: =SUMIFS(Backlog!$I:$I,Backlog!$B:$B,$A7,Backlog!$F:$F,"Jordy") -> 20 | D7: =SUMIFS(Backlog!$I:$I,Backlog!$B:$B,$A7,Backlog!$F:$F,"Meli") -> 20 | E7: =SUMIFS(Backlog!$I:$I,Backlog!$B:$B,$A7,Backlog!$F:$F,"Cami") -> 20 | F7: =SUMIFS(Backlog!$I:$I,Backlog!$B:$B,$A7,Backlog!$F:$F,"Sofi") -> 20 | G7: =SUM(C7:F7) -> 80
A8: 3 | B8: =IF(Sprints!F8="normal",Resumen!$B$10,Resumen!$B$11) -> 14 | C8: =SUMIFS(Backlog!$I:$I,Backlog!$B:$B,$A8,Backlog!$F:$F,"Jordy") -> 14 | D8: =SUMIFS(Backlog!$I:$I,Backlog!$B:$B,$A8,Backlog!$F:$F,"Meli") -> 14 | E8: =SUMIFS(Backlog!$I:$I,Backlog!$B:$B,$A8,Backlog!$F:$F,"Cami") -> 14 | F8: =SUMIFS(Backlog!$I:$I,Backlog!$B:$B,$A8,Backlog!$F:$F,"Sofi") -> 14 | G8: =SUM(C8:F8) -> 56
A9: 4 | B9: =IF(Sprints!F9="normal",Resumen!$B$10,Resumen!$B$11) -> 20 | C9: =SUMIFS(Backlog!$I:$I,Backlog!$B:$B,$A9,Backlog!$F:$F,"Jordy") -> 20 | D9: =SUMIFS(Backlog!$I:$I,Backlog!$B:$B,$A9,Backlog!$F:$F,"Meli") -> 20 | E9: =SUMIFS(Backlog!$I:$I,Backlog!$B:$B,$A9,Backlog!$F:$F,"Cami") -> 20 | F9: =SUMIFS(Backlog!$I:$I,Backlog!$B:$B,$A9,Backlog!$F:$F,"Sofi") -> 20 | G9: =SUM(C9:F9) -> 80
A10: 5 | B10: =IF(Sprints!F10="normal",Resumen!$B$10,Resumen!$B$11) -> 20 | C10: =SUMIFS(Backlog!$I:$I,Backlog!$B:$B,$A10,Backlog!$F:$F,"Jordy") -> 20 | D10: =SUMIFS(Backlog!$I:$I,Backlog!$B:$B,$A10,Backlog!$F:$F,"Meli") -> 20 | E10: =SUMIFS(Backlog!$I:$I,Backlog!$B:$B,$A10,Backlog!$F:$F,"Cami") -> 20 | F10: =SUMIFS(Backlog!$I:$I,Backlog!$B:$B,$A10,Backlog!$F:$F,"Sofi") -> 20 | G10: =SUM(C10:F10) -> 80
A11: 6 | B11: =IF(Sprints!F11="normal",Resumen!$B$10,Resumen!$B$11) -> 14 | C11: =SUMIFS(Backlog!$I:$I,Backlog!$B:$B,$A11,Backlog!$F:$F,"Jordy") -> 14 | D11: =SUMIFS(Backlog!$I:$I,Backlog!$B:$B,$A11,Backlog!$F:$F,"Meli") -> 14 | E11: =SUMIFS(Backlog!$I:$I,Backlog!$B:$B,$A11,Backlog!$F:$F,"Cami") -> 14 | F11: =SUMIFS(Backlog!$I:$I,Backlog!$B:$B,$A11,Backlog!$F:$F,"Sofi") -> 14 | G11: =SUM(C11:F11) -> 56
A12: 7 | B12: =IF(Sprints!F12="normal",Resumen!$B$10,Resumen!$B$11) -> 14 | C12: =SUMIFS(Backlog!$I:$I,Backlog!$B:$B,$A12,Backlog!$F:$F,"Jordy") -> 14 | D12: =SUMIFS(Backlog!$I:$I,Backlog!$B:$B,$A12,Backlog!$F:$F,"Meli") -> 14 | E12: =SUMIFS(Backlog!$I:$I,Backlog!$B:$B,$A12,Backlog!$F:$F,"Cami") -> 14 | F12: =SUMIFS(Backlog!$I:$I,Backlog!$B:$B,$A12,Backlog!$F:$F,"Sofi") -> 14 | G12: =SUM(C12:F12) -> 56
A13: 8 | B13: =IF(Sprints!F13="normal",Resumen!$B$10,Resumen!$B$11) -> 20 | C13: =SUMIFS(Backlog!$I:$I,Backlog!$B:$B,$A13,Backlog!$F:$F,"Jordy") -> 20 | D13: =SUMIFS(Backlog!$I:$I,Backlog!$B:$B,$A13,Backlog!$F:$F,"Meli") -> 20 | E13: =SUMIFS(Backlog!$I:$I,Backlog!$B:$B,$A13,Backlog!$F:$F,"Cami") -> 20 | F13: =SUMIFS(Backlog!$I:$I,Backlog!$B:$B,$A13,Backlog!$F:$F,"Sofi") -> 20 | G13: =SUM(C13:F13) -> 80
A14: 9 | B14: =IF(Sprints!F14="normal",Resumen!$B$10,Resumen!$B$11) -> 20 | C14: =SUMIFS(Backlog!$I:$I,Backlog!$B:$B,$A14,Backlog!$F:$F,"Jordy") -> 20 | D14: =SUMIFS(Backlog!$I:$I,Backlog!$B:$B,$A14,Backlog!$F:$F,"Meli") -> 20 | E14: =SUMIFS(Backlog!$I:$I,Backlog!$B:$B,$A14,Backlog!$F:$F,"Cami") -> 20 | F14: =SUMIFS(Backlog!$I:$I,Backlog!$B:$B,$A14,Backlog!$F:$F,"Sofi") -> 20 | G14: =SUM(C14:F14) -> 80
A15: 10 | B15: =IF(Sprints!F15="normal",Resumen!$B$10,Resumen!$B$11) -> 20 | C15: =SUMIFS(Backlog!$I:$I,Backlog!$B:$B,$A15,Backlog!$F:$F,"Jordy") -> 20 | D15: =SUMIFS(Backlog!$I:$I,Backlog!$B:$B,$A15,Backlog!$F:$F,"Meli") -> 20 | E15: =SUMIFS(Backlog!$I:$I,Backlog!$B:$B,$A15,Backlog!$F:$F,"Cami") -> 20 | F15: =SUMIFS(Backlog!$I:$I,Backlog!$B:$B,$A15,Backlog!$F:$F,"Sofi") -> 20 | G15: =SUM(C15:F15) -> 80
A16: 11 | B16: =IF(Sprints!F16="normal",Resumen!$B$10,Resumen!$B$11) -> 20 | C16: =SUMIFS(Backlog!$I:$I,Backlog!$B:$B,$A16,Backlog!$F:$F,"Jordy") -> 20 | D16: =SUMIFS(Backlog!$I:$I,Backlog!$B:$B,$A16,Backlog!$F:$F,"Meli") -> 20 | E16: =SUMIFS(Backlog!$I:$I,Backlog!$B:$B,$A16,Backlog!$F:$F,"Cami") -> 20 | F16: =SUMIFS(Backlog!$I:$I,Backlog!$B:$B,$A16,Backlog!$F:$F,"Sofi") -> 20 | G16: =SUM(C16:F16) -> 80
... A23: 18 | B23: =IF(Sprints!F23="normal",Resumen!$B$10,Resumen!$B$11) -> 14 | C23: =SUMIFS(Backlog!$I:$I,Backlog!$B:$B,$A23,Backlog!$F:$F,"Jordy") -> 14 | D23: =SUMIFS(Backlog!$I:$I,Backlog!$B:$B,$A23,Backlog!$F:$F,"Meli") -> 14 | E23: =SUMIFS(Backlog!$I:$I,Backlog!$B:$B,$A23,Backlog!$F:$F,"Cami") -> 14 | F23: =SUMIFS(Backlog!$I:$I,Backlog!$B:$B,$A23,Backlog!$F:$F,"Sofi") -> 14 | G23: =SUM(C23:F23) -> 56
A24: Total | B24: =SUM(B5:B23) -> 344 | C24: =SUM(C5:C23) -> 344 | D24: =SUM(D5:D23) -> 344 | E24: =SUM(E5:E23) -> 344 | F24: =SUM(F5:F23) -> 344 | G24: =SUM(G5:G23) -> 1376

Sheet Gantt
A1: Diagrama de Gantt (semanal)
A2: Las barras se dibujan con formato condicional a partir de Inicio/Fin; columna amarilla = semana actual | C2: Jordy | D2: Meli | E2: Cami | F2: Sofi
B3: Leyenda → | K3: Apr | O3: May | S3: Jun | X3: Jul | AB3: Aug | AG3: Sep | AK3: Oct | AO3: Nov | AT3: Dec
A4: ID | B4: Tarea | C4: Responsable | D4: Inicio | E4: Fin | F4: Horas | G4: 46090 | H4: 46097 | I4: 46104 | J4: 46111 | K4: 46118 | L4: 46125 | M4: 46132 | N4: 46139 | O4: 46146 | P4: 46153 | Q4: 46160 | R4: 46167 | S4: 46174 | T4: 46181 | U4: 46188 | V4: 46195 | W4: 46202 | X4: 46209 | Y4: 46216 | Z4: 46223 | AA4: 46230 | AB4: 46237 | AC4: 46244 | AD4: 46251 | AE4: 46258 | AF4: 46265 | AG4: 46272 | AH4: 46279 | AI4: 46286 | AJ4: 46293 | AK4: 46300 | AL4: 46307 | AM4: 46314 | AN4: 46321 | AO4: 46328 | AP4: 46335 | AQ4: 46342 | AR4: 46349 | AS4: 46356 | AT4: 46363 | AU4: 46370
B5: Fase 1 — Inicio y análisis | C5: Fase | D5: =Sprints!C5 -> 46093 | E5: =Sprints!D8 -> 46148 | F5: =SUM(Sprints!I5:I8) -> 296
B6: ="Sprint 0 — "&Sprints!E5 -> Sprint 0 — Inicio del proyecto y relevamiento inicial | C6: Sprint | D6: =Sprints!C5 -> 46093 | E6: =Sprints!D5 -> 46106 | F6: =Sprints!I5 -> 80
A7: =Backlog!A5 -> T-001 | B7: =Backlog!E5 -> Kickoff, conformación del equipo y tablero Scrum en GitHub Projects | C7: =Backlog!F5 -> Jordy | D7: =Backlog!G5 -> 46093 | E7: =Backlog!H5 -> 46106 | F7: =Backlog!I5 -> 8
A8: =Backlog!A6 -> T-002 | B8: =Backlog!E6 -> Entrevista inicial con la institución y presentación del proyecto | C8: =Backlog!F6 -> Jordy | D8: =Backlog!G6 -> 46093 | E8: =Backlog!H6 -> 46106 | F8: =Backlog!I6 -> 12
A9: =Backlog!A7 -> T-003 | B9: =Backlog!E7 -> Relevamiento de documentación existente (planillas, legajos en papel) | C9: =Backlog!F7 -> Meli | D9: =Backlog!G7 -> 46093 | E9: =Backlog!H7 -> 46106 | F9: =Backlog!I7 -> 10
A10: =Backlog!A8 -> T-004 | B10: =Backlog!E8 -> Acta de constitución y alcance preliminar | C10: =Backlog!F8 -> Meli | D10: =Backlog!G8 -> 46093 | E10: =Backlog!H8 -> 46106 | F10: =Backlog!I8 -> 10
A11: =Backlog!A9 -> T-005 | B11: =Backlog!E9 -> Relevamiento de actores, roles y usuarios del sistema | C11: =Backlog!F9 -> Sofi | D11: =Backlog!G9 -> 46093 | E11: =Backlog!H9 -> 46106 | F11: =Backlog!I9 -> 20
A12: =Backlog!A10 -> T-006 | B12: =Backlog!E10 -> Relevamiento de herramientas actuales y problemáticas | C12: =Backlog!F10 -> Cami | D12: =Backlog!G10 -> 46093 | E12: =Backlog!H10 -> 46106 | F12: =Backlog!I10 -> 12
A13: =Backlog!A11 -> T-007 | B13: =Backlog!E11 -> Presentación del proyecto (Encuentro 1) | C13: =Backlog!F11 -> Cami | D13: =Backlog!G11 -> 46093 | E13: =Backlog!H11 -> 46106 | F13: =Backlog!I11 -> 8
B14: ="Sprint 1 — "&Sprints!E6 -> Sprint 1 — Procesos del negocio | C14: Sprint | D14: =Sprints!C6 -> 46107 | E14: =Sprints!D6 -> 46120 | F14: =Sprints!I6 -> 80
A15: =Backlog!A12 -> T-008 | B15: =Backlog!E12 -> Proceso de ingreso y admisión (Ley 9944 / Ley 26.061) | C15: =Backlog!F12 -> Jordy | D15: =Backlog!G12 -> 46107 | E15: =Backlog!H12 -> 46120 | F15: =Backlog!I12 -> 20
A16: =Backlog!A13 -> T-009 | B16: =Backlog!E13 -> Procesos de legajo, documentos e informes | C16: =Backlog!F13 -> Meli | D16: =Backlog!G13 -> 46107 | E16: =Backlog!H13 -> 46120 | F16: =Backlog!I13 -> 20
A17: =Backlog!A14 -> T-010 | B17: =Backlog!E14 -> Procesos de acompañamiento diario, salud e incidentes | C17: =Backlog!F14 -> Sofi | D17: =Backlog!G14 -> 46107 | E17: =Backlog!H14 -> 46120 | F17: =Backlog!I14 -> 20
A18: =Backlog!A15 -> T-011 | B18: =Backlog!E15 -> Procesos de egreso, tutela y coordinación judicial / SENAF | C18: =Backlog!F15 -> Cami | D18: =Backlog!G15 -> 46107 | E18: =Backlog!H15 -> 46120 | F18: =Backlog!I15 -> 20
B19: ="Sprint 2 — "&Sprints!E7 -> Sprint 2 — Requerimientos y modelo de datos | C19: Sprint | D19: =Sprints!C7 -> 46121 | E19: =Sprints!D7 -> 46134 | F19: =Sprints!I7 -> 80
A20: =Backlog!A16 -> T-012 | B20: =Backlog!E16 -> Modelo de datos (DER) y diccionario de datos | C20: =Backlog!F16 -> Jordy | D20: =Backlog!G16 -> 46121 | E20: =Backlog!H16 -> 46134 | F20: =Backlog!I16 -> 20
A21: =Backlog!A17 -> T-013 | B21: =Backlog!E17 -> Specs 01–04: acceso y roles, trazabilidad, NNyA y tutores, legajo | C21: =Backlog!F17 -> Sofi | D21: =Backlog!G17 -> 46121 | E21: =Backlog!H17 -> 46134 | F21: =Backlog!I17 -> 20
A22: =Backlog!A18 -> T-014 | B22: =Backlog!E18 -> Catálogo de excepciones y reglas de negocio | C22: =Backlog!F18 -> Meli | D22: =Backlog!G18 -> 46121 | E22: =Backlog!H18 -> 46134 | F22: =Backlog!I18 -> 20
A23: =Backlog!A19 -> T-015 | B23: =Backlog!E19 -> Wireframes de baja fidelidad (web) | C23: =Backlog!F19 -> Cami | D23: =Backlog!G19 -> 46121 | E23: =Backlog!H19 -> 46134 | F23: =Backlog!I19 -> 20
B24: ="Sprint 3 — "&Sprints!E8 -> Sprint 3 — Arquitectura y especificación funcional | C24: Sprint | D24: =Sprints!C8 -> 46135 | E24: =Sprints!D8 -> 46148 | F24: =Sprints!I8 -> 56
A25: =Backlog!A20 -> T-016 | B25: =Backlog!E20 -> Arquitectura del sistema (Next.js + Supabase + Expo) v1.1 | C25: =Backlog!F20 -> Jordy | D25: =Backlog!G20 -> 46135 | E25: =Backlog!H20 -> 46148 | F25: =Backlog!I20 -> 14
A26: =Backlog!A21 -> T-017 | B26: =Backlog!E21 -> Specs 05–08: documentos, informes, salud, acompañamiento diario | C26: =Backlog!F21 -> Sofi | D26: =Backlog!G21 -> 46135 | E26: =Backlog!H21 -> 46148 | F26: =Backlog!I21 -> 14
A27: =Backlog!A22 -> T-018 | B27: =Backlog!E22 -> Specs 09–12: incidentes, egreso, coordinación judicial, evaluación | C27: =Backlog!F22 -> Meli | D27: =Backlog!G22 -> 46135 | E27: =Backlog!H22 -> 46148 | F27: =Backlog!I22 -> 14
A28: =Backlog!A23 -> T-019 | B28: =Backlog!E23 -> Prototipo de alta fidelidad y guía de estilos | C28: =Backlog!F23 -> Cami | D28: =Backlog!G23 -> 46135 | E28: =Backlog!H23 -> 46148 | F28: =Backlog!I23 -> 14
B29: Fase 2 — Construcción web | C29: Fase | D29: =Sprints!C9 -> 46149 | E29: =Sprints!D15 -> 46260 | F29: =SUM(Sprints!I9:I15) -> 512
B30: ="Sprint 4 — "&Sprints!E9 -> Sprint 4 — Setup técnico y sistema de diseño | C30: Sprint | D30: =Sprints!C9 -> 46149 | E30: =Sprints!D9 -> 46162 | F30: =Sprints!I9 -> 80
A31: =Backlog!A24 -> T-020 | B31: =Backlog!E24 -> Setup Next.js + Supabase + Vercel y migraciones iniciales | C31: =Backlog!F24 -> Jordy | D31: =Backlog!G24 -> 46149 | E31: =Backlog!H24 -> 46162 | F31: =Backlog!I24 -> 20
A32: =Backlog!A25 -> T-021 | B32: =Backlog!E25 -> Sistema de diseño: tokens y componentes base | C32: =Backlog!F25 -> Cami | D32: =Backlog!G25 -> 46149 | E32: =Backlog!H25 -> 46162 | F32: =Backlog!I25 -> 20
A33: =Backlog!A26 -> T-022 | B33: =Backlog!E26 -> Plan de pruebas y criterios de aceptación | C33: =Backlog!F26 -> Meli | D33: =Backlog!G26 -> 46149 | E33: =Backlog!H26 -> 46162 | F33: =Backlog!I26 -> 14
A34: =Backlog!A27 -> T-023 | B34: =Backlog!E27 -> Estimación por Puntos de Función (PF sin ajustar) | C34: =Backlog!F27 -> Meli | D34: =Backlog!G27 -> 46149 | E34: =Backlog!H27 -> 46162 | F34: =Backlog!I27 -> 6
A35: =Backlog!A28 -> T-024 | B35: =Backlog!E28 -> Plan de trabajo ISO 12207 y línea base de valor ganado | C35: =Backlog!F28 -> Sofi | D35: =Backlog!G28 -> 46149 | E35: =Backlog!H28 -> 46162 | F35: =Backlog!I28 -> 20
B36: ="Sprint 5 — "&Sprints!E10 -> Sprint 5 — Autenticación y ABM maestras | C36: Sprint | D36: =Sprints!C10 -> 46163 | E36: =Sprints!D10 -> 46176 | F36: =Sprints!I10 -> 80
A37: =Backlog!A29 -> T-025 | B37: =Backlog!E29 -> Autenticación, roles y políticas RLS base | C37: =Backlog!F29 -> Jordy | D37: =Backlog!G29 -> 46163 | E37: =Backlog!H29 -> 46176 | F37: =Backlog!I29 -> 20
A38: =Backlog!A30 -> T-026 | B38: =Backlog!E30 -> Layout, navegación y ABM de usuarios y roles | C38: =Backlog!F30 -> Cami | D38: =Backlog!G30 -> 46163 | E38: =Backlog!H30 -> 46176 | F38: =Backlog!I30 -> 20
A39: =Backlog!A31 -> T-027 | B39: =Backlog!E31 -> ABM de NNyA y tutores | C39: =Backlog!F31 -> Sofi | D39: =Backlog!G31 -> 46163 | E39: =Backlog!H31 -> 46176 | F39: =Backlog!I31 -> 20
A40: =Backlog!A32 -> T-028 | B40: =Backlog!E32 -> Pruebas manuales del sprint y datos de prueba (seed) | C40: =Backlog!F32 -> Meli | D40: =Backlog!G32 -> 46163 | E40: =Backlog!H32 -> 46176 | F40: =Backlog!I32 -> 20
...
